Workbook
Name SSLink_0: #REF!
Name SSLink_1: #REF!
Name SSLink_2: #REF!

Sheet SHIP DETAILS
B2: Vessel Name | C2: MV. RISHABH
B3: IMO | C3: 9324578 | F3: FOR OFFHIRE
B4: Flag | C4: MARSHALL ISLANDS | F4: Place of Redelivery | G4: As per Master's Report
B5: Port of Registry | C5: MAJURO | F5: Date of Redelivery | G5: As per Master's Report
B6: GRT | C6: 34512 | F6: Time of Redelivery | G6: As per Master's Report
B7: NRT | C7: 19874
B8: Voyage No. | C8: 15 L
B9: Owners | C9: PRAYAN SHIPPING INC
B10: Charterers Name | C10: DAVA PTE. LTD | G10: VLSFO | H10: HSFO | I10: LSMGO
B11: FWE | C11: 25th JANUARY 2026 | D11: 0.41666667 | F11: BROB: | G11: 500.124 | H11: 0 | I11: 100.254 | J11: M.Tons
B12: Survey Started | C12: 28th JANUARY 2026 | D12: 0.5 | F12: BROB: | G12: 450.547 | H12: 0 | I12: 100.154 | J12: M.Tons
B13: Survey Completed | C13: 28th JANUARY 2026 | D13: 0.58333333
B14: Place of Survey | C14: B#6, GANGAVARAM PORT, INDIA
B15: Draft Aft | C15: 12.3
B16: Draft Fwd | C16: 10.2
B17: Master Name | C17: KAMAL PANDEY
B18: Chief Engineer Name | C18: MUKESH KUMAR
B19: Surveyor Name | C19: ASHOK JANAPALA
B20: List | C20: 0
B21: No. Of Holds | C21: 5
B22: Builder | C22: SOME BUILDER NAME
B23: Keel laid Month | C23: MAY
B24: Keel laid Year | C24: 2015
B25: Manager/Operator Name | C25: PRAYAN SHIPPING INC
B26: Callsign | C26: V75A45
B27: LOA | C27: 190.9
B28: Breadth Moulded | C28: 32.26
B29: Depth Moulded | C29: 18.2
B30: Summer Draft | C30: 12.2
B31: Summer Deadweight | C31: 51874
B32: Class | C32: NKK
B35: NOTE: THIS PAGE IS ONLY FOR INFORMATION TO FILL,NO NEED TO TAKE PRINTOUT.

Sheet TABLES 54B
A6: ='SHIP DETAILS'!C2 -> MV. RISHABH
A7: =CONCATENATE("IMO No. ",'SHIP DETAILS'!C3,"") -> IMO No. 9324578
A8: B U N K E R S U R V E Y
B10: Owners | C10: ='SHIP DETAILS'!C9 -> PRAYAN SHIPPING INC
B11: Charterers | C11: ='SHIP DETAILS'!C10 -> DAVA PTE. LTD | G11: VLSFO | H11: HSFO | I11: LSMGO
B12: FWE | C12: ='SHIP DETAILS'!C11 -> 25th JANUARY 2026 | E12: ='SHIP DETAILS'!D11 -> 0.41666667 | F12: Hrs LT BROB: | G12: ='SHIP DETAILS'!G11 -> 500.124 | H12: ='SHIP DETAILS'!H11 -> 0 | I12: ='SHIP DETAILS'!I11 -> 100.254 | J12: M.Tons | L12: Vessel Name | M12: =A6 -> MV. RISHABH
B13: Survey Started | C13: ='SHIP DETAILS'!C12 -> 28th JANUARY 2026 | E13: ='SHIP DETAILS'!D12 -> 0.5 | F13: Hrs LT BROB: | G13: ='SHIP DETAILS'!G12 -> 450.547 | H13: ='SHIP DETAILS'!H12 -> 0 | I13: ='SHIP DETAILS'!I12 -> 100.154 | J13: M.Tons | L13: Charterer | M13: =C11 -> DAVA PTE. LTD
B14: Survey Completed | C14: ='SHIP DETAILS'!C13 -> 28th JANUARY 2026 | E14: ='SHIP DETAILS'!D13 -> 0.58333333 | F14: Hrs LT | M14: RESULTS
B15: Place of Survey | C15: ='SHIP DETAILS'!C14 -> B#6, GANGAVARAM PORT, INDIA | M15: AT THE TIME OF SURVEY
B16: Voyage No. | C16: ='SHIP DETAILS'!C8 -> 15 L
B17: Draft Aft | C17: ='SHIP DETAILS'!C15 -> 12.3 | D17: Meters | H17: Trim: | I17: =C17-C18 -> 2.1 | J17: Meters | M17: =G11 -> VLSFO | N17: =H11 -> HSFO | O17: =I11 -> LSMGO
B18: Draft Fwd | C18: ='SHIP DETAILS'!C16 -> 10.2 | D18: Meters | H18: List | I18: ='SHIP DETAILS'!C20 -> 0 | J18: Degrees | L18: Actual | M18: =J40 -> 466.296 | N18: =J50 -> 0 | O18: =J63 -> 101.592 | P18: ROB as per bunker survey
L19: Log Book | M19: =G13 -> 450.547 | N19: =H13 -> 0 | O19: =I13 -> 100.154 | P19: ROB as per E/R log book
B20: Very Low Sulpher Fuel Oil | L20: Difference | M20: =M18-M19 -> 15.749 | N20: =N18-N19 -> 0 | O20: =O18-O19 -> 1.438
B21: Tank | C21: Ref. Height | D21: Sdg. Corr'd | E21: Volume | F21: Density | G21: Temp | H21: V.C.F. | I21: G.S.V | J21: Metric | M21: Total | O21: =SUM(M20:O20) -> 63.423 | U21: 186.9696
B22: Name: | C22: (m) | D22: (m) | E22: Cubic Metres | F22: @15°C | G22: Deg(C ) | H22: T(54B ) | I22: m³ @ 15°C | J22: Tons | U22: 0.4862
B23: NO 1 HFO P | C23: 18 | D23: 1 | E23: 100 | F23: 0.9324 | G23: 27 | H23: =IF(G23="","",ROUND(EXP(-U23*(G23-15)*(1+0.8*U23*(G23-15))),4)) -> 0.9911 | I23: =IF(G23="","",ROUND(E23*H23,3)) -> 99.11 | J23: =X23 -> 92.301 | T23: =ROUND(+F23/2*1000,0)*2 -> 932 | U23: =ROUND($U$21/(T23*T23)+($U$22/T23),8) -> 0.00073692 | W23: =+F23-0.0011 -> 0.9313 | X23: =IF(G23="","",ROUND((I23*W23),3)) -> 92.301
B24: NO 1 HFO S | C24: 18 | D24: 1 | E24: 100 | F24: 0.9324 | G24: 27 | H24: =IF(G24="","",ROUND(EXP(-U24*(G24-15)*(1+0.8*U24*(G24-15))),4)) -> 0.9911 | I24: =IF(G24="","",ROUND(E24*H24,3)) -> 99.11 | J24: =X24 -> 92.301 | T24: =ROUND(+F24/2*1000,0)*2 -> 932 | U24: =ROUND($U$21/(T24*T24)+($U$22/T24),8) -> 0.00073692 | W24: =+F24-0.0011 -> 0.9313 | X24: =IF(G24="","",ROUND((I24*W24),3)) -> 92.301
B25: NO 2 HFO P | C25: 18 | D25: 1 | E25: 100 | F25: 0.9324 | G25: 27 | H25: =IF(G25="","",ROUND(EXP(-U25*(G25-15)*(1+0.8*U25*(G25-15))),4)) -> 0.9911 | I25: =IF(G25="","",ROUND(E25*H25,3)) -> 99.11 | J25: =X25 -> 92.301 | T25: =ROUND(+F25/2*1000,0)*2 -> 932 | U25: =ROUND($U$21/(T25*T25)+($U$22/T25),8) -> 0.00073692 | W25: =+F25-0.0011 -> 0.9313 | X25: =IF(G25="","",ROUND((I25*W25),3)) -> 92.301
B26: NO 2 HFO S | C26: 18 | D26: 1 | E26: 100 | F26: 0.9324 | G26: 27 | H26: =IF(G26="","",ROUND(EXP(-U26*(G26-15)*(1+0.8*U26*(G26-15))),4)) -> 0.9911 | I26: =IF(G26="","",ROUND(E26*H26,3)) -> 99.11 | J26: =X26 -> 92.301 | T26: =ROUND(+F26/2*1000,0)*2 -> 932 | U26: =ROUND($U$21/(T26*T26)+($U$22/T26),8) -> 0.00073692 | W26: =+F26-0.0011 -> 0.9313 | X26: =IF(G26="","",ROUND((I26*W26),3)) -> 92.301
B27: NO 3 HFO P | C27: 18 | D27: 1 | E27: 12 | F27: 0.9324 | G27: 27 | H27: =IF(G27="","",ROUND(EXP(-U27*(G27-15)*(1+0.8*U27*(G27-15))),4)) -> 0.9911 | I27: =IF(G27="","",ROUND(E27*H27,3)) -> 11.893 | J27: =X27 -> 11.076 | T27: =ROUND(+F27/2*1000,0)*2 -> 932 | U27: =ROUND($U$21/(T27*T27)+($U$22/T27),8) -> 0.00073692 | W27: =+F27-0.0011 -> 0.9313 | X27: =IF(G27="","",ROUND((I27*W27),3)) -> 11.076
B28: NO 3 HFO S | C28: 8 | D28: 1 | E28: 12 | F28: 0.9324 | G28: 27 | H28: =IF(G28="","",ROUND(EXP(-U28*(G28-15)*(1+0.8*U28*(G28-15))),4)) -> 0.9911 | I28: =IF(G28="","",ROUND(E28*H28,3)) -> 11.893 | J28: =X28 -> 11.076 | T28: =ROUND(+F28/2*1000,0)*2 -> 932 | U28: =ROUND($U$21/(T28*T28)+($U$22/T28),8) -> 0.00073692 | W28: =+F28-0.0011 -> 0.9313 | X28: =IF(G28="","",ROUND((I28*W28),3)) -> 11.076
B29: SETT 1 | C29: GAUGE | D29: GAUGE | E29: 20 | F29: 0.9324 | G29: 90 | H29: =IF(G29="","",ROUND(EXP(-U29*(G29-15)*(1+0.8*U29*(G29-15))),4)) -> 0.9439 | I29: =IF(G29="","",ROUND(E29*H29,3)) -> 18.878 | J29: =X29 -> 17.581 | T29: =ROUND(+F29/2*1000,0)*2 -> 932 | U29: =ROUND($U$21/(T29*T29)+($U$22/T29),8) -> 0.00073692 | W29: =+F29-0.0011 -> 0.9313 | X29: =IF(G29="","",ROUND((I29*W29),3)) -> 17.581
B30: SETT 2 | C30: GAUGE | D30: GAUGE | E30: 20 | F30: 0.9324 | G30: 90 | H30: =IF(G30="","",ROUND(EXP(-U30*(G30-15)*(1+0.8*U30*(G30-15))),4)) -> 0.9439 | I30: =IF(G30="","",ROUND(E30*H30,3)) -> 18.878 | J30: =X30 -> 17.581 | T30: =ROUND(+F30/2*1000,0)*2 -> 932 | U30: =ROUND($U$21/(T30*T30)+($U$22/T30),8) -> 0.00073692 | W30: =+F30-0.0011 -> 0.9313 | X30: =IF(G30="","",ROUND((I30*W30),3)) -> 17.581
B31: SERV 1 | C31: GAUGE | D31: GAUGE | E31: 20 | F31: 0.9324 | G31: 90 | H31: =IF(G31="","",ROUND(EXP(-U31*(G31-15)*(1+0.8*U31*(G31-15))),4)) -> 0.9439 | I31: =IF(G31="","",ROUND(E31*H31,3)) -> 18.878 | J31: =X31 -> 17.581 | T31: =ROUND(+F31/2*1000,0)*2 -> 932 | U31: =ROUND($U$21/(T31*T31)+($U$22/T31),8) -> 0.00073692 | W31: =+F31-0.0011 -> 0.9313 | X31: =IF(G31="","",ROUND((I31*W31),3)) -> 17.581
B32: SERV 2 | C32: GAUGE | D32: GAUGE | E32: 20 | F32: 0.9324 | G32: 90 | H32: =IF(G32="","",ROUND(EXP(-U32*(G32-15)*(1+0.8*U32*(G32-15))),4)) -> 0.9439 | I32: =IF(G32="","",ROUND(E32*H32,3)) -> 18.878 | J32: =X32 -> 17.581 | T32: =ROUND(+F32/2*1000,0)*2 -> 932 | U32: =ROUND($U$21/(T32*T32)+($U$22/T32),8) -> 0.00073692 | W32: =+F32-0.0011 -> 0.9313 | X32: =IF(G32="","",ROUND((I32*W32),3)) -> 17.581
B33: OVERFLOW | C33: 4.87 | D33: 0.21 S | E33: 5 | F33: 0.9324 | G33: 27 | H33: =IF(G33="","",ROUND(EXP(-U33*(G33-15)*(1+0.8*U33*(G33-15))),4)) -> 0.9911 | I33: =IF(G33="","",ROUND(E33*H33,3)) -> 4.956 | J33: =X33 -> 4.616 | T33: =ROUND(+F33/2*1000,0)*2 -> 932 | U33: =ROUND($U$21/(T33*T33)+($U$22/T33),8) -> 0.00073692 | W33: =+F33-0.0011 -> 0.9313 | X33: =IF(G33="","",ROUND((I33*W33),3)) -> 4.616
H34: =IF(G34="","",ROUND(EXP(-U34*(G34-15)*(1+0.8*U34*(G34-15))),4)) | I34: =IF(G34="","",ROUND(E34*H34,3)) | J34: =X34 | T34: =ROUND(+F34/2*1000,0)*2 -> 0 | U34: =ROUND($U$21/(T34*T34)+($U$22/T34),8) -> #DIV/0! | W34: =+F34-0.0011 -> -0.0011 | X34: =IF(G34="","",ROUND((I34*W34),3))
H35: =IF(G35="","",ROUND(EXP(-U35*(G35-15)*(1+0.8*U35*(G35-15))),4)) | I35: =IF(G35="","",ROUND(E35*H35,3)) | J35: =X35 | T35: =ROUND(+F35/2*1000,0)*2 -> 0 | U35: =ROUND($U$21/(T35*T35)+($U$22/T35),8) -> #DIV/0! | W35: =+F35-0.0011 -> -0.0011 | X35: =IF(G35="","",ROUND((I35*W35),3))
H36: =IF(G36="","",ROUND(EXP(-U36*(G36-15)*(1+0.8*U36*(G36-15))),4)) | I36: =IF(G36="","",ROUND(E36*H36,3)) | J36: =X36 | T36: =ROUND(+F36/2*1000,0)*2 -> 0 | U36: =ROUND($U$21/(T36*T36)+($U$22/T36),8) -> #DIV/0! | W36: =+F36-0.0011 -> -0.0011 | X36: =IF(G36="","",ROUND((I36*W36),3))
H37: =IF(G37="","",ROUND(EXP(-U37*(G37-15)*(1+0.8*U37*(G37-15))),4)) | I37: =IF(G37="","",ROUND(E37*H37,3)) | J37: =X37 | T37: =ROUND(+F37/2*1000,0)*2 -> 0 | U37: =ROUND($U$21/(T37*T37)+($U$22/T37),8) -> #DIV/0! | W37: =+F37-0.0011 -> -0.0011 | X37: =IF(G37="","",ROUND((I37*W37),3))
H38: =IF(G38="","",ROUND(EXP(-U38*(G38-15)*(1+0.8*U38*(G38-15))),4)) | I38: =IF(G38="","",ROUND(E38*H38,3)) | J38: =X38 | T38: =ROUND(+F38/2*1000,0)*2 -> 0 | U38: =ROUND($U$21/(T38*T38)+($U$22/T38),8) -> #DIV/0! | W38: =+F38-0.0011 -> -0.0011 | X38: =IF(G38="","",ROUND((I38*W38),3))
F39: TOTAL Cubic Metres @ 15°C | I39: =SUM(I23:I38) -> 500.694
H40: TOTAL Metric Tons | J40: =SUM(J23:J39) -> 466.296
B42: High Sulphur Fuel Oil
B43: Tank | C43: Ref. Height | D43: Sdg. Corr'd | E43: Volume | F43: Density | G43: Temp | H43: V.C.F. | I43: G.S.V | J43: Metric | U43: 186.9696
B44: Name: | C44: (m) | D44: (m) | E44: Cubic Metres | F44: @15°C | G44: Deg(C ) | H44: T(54B ) | I44: m³ @ 15°C | J44: Tons | U44: 0.4862
T45: =ROUND(+F45/2*1000,0)*2 -> 0 | U45: =ROUND($U$21/(T45*T45)+($U$22/T45),8) -> #DIV/0! | W45: =+F45-0.0011 -> -0.0011
T46: =ROUND(+F46/2*1000,0)*2 -> 0 | U46: =ROUND($U$21/(T46*T46)+($U$22/T46),8) -> #DIV/0! | W46: =+F46-0.0011 -> -0.0011
T47: =ROUND(+F47/2*1000,0)*2 -> 0 | U47: =ROUND($U$21/(T47*T47)+($U$22/T47),8) -> #DIV/0! | W47: =+F47-0.0011 -> -0.0011
...

Sheet OFFHIRE 
A6: CERTIFICATE OF OFF-HIRE BUNKER QUANTITY
A8: Place of Redelivery: | D8: ='SHIP DETAILS'!G4 -> As per Master's Report
A9: Date of Redelivery: | D9: ='SHIP DETAILS'!G5 -> As per Master's Report
A10: Time of Redelivery: | D10: ='SHIP DETAILS'!G6 -> As per Master's Report
A12: Date / Time of Survey Completed: | E12: ='SHIP DETAILS'!C13 -> 28th JANUARY 2026 | I12: ='SHIP DETAILS'!D13 -> 0.58333333 | J12: Hrs LT
A14: =CONCATENATE("This is to certify that ",'SHIP DETAILS'!C2,", under ",'SHIP DETAILS'!C4," Flag, Port of Registry ",'SHIP DETAILS'!C5,", GRT ",'SHIP DETAILS'!C6,", NRT ",'SHIP DETAILS'!C7,", Redelivered to Messrs ",'SHIP DETAILS'!C9,", by Messrs ",'SHIP DETAILS'!C10,", subject to all terms, conditions and exceptions agreed between Owners and Charterers as per governing Charter Party.") -> This is to certify that MV. RISHABH, under MARSHALL ISLANDS Flag, Port of Registry MAJURO, GRT 34512, NRT 19874, Redelivered to Messrs PRAYAN SHIPPING INC, by Messrs DAVA PTE. LTD, subject to all terms, conditions and exceptions agreed between Owners and Charterers as per governing Charter Party.
A16: =CONCATENATE("The undersigned Independent Marine Surveyor, acting ",'SHIP DETAILS'!C10,", to carried out Bunker Survey in order to determine the amount of bunkers remain on board."," All bunker tanks were carefully sounded with the presence of Chief Engineer and the following"," quantities found and agreed, as calculated from the vessel's calibration tables.") -> The undersigned Independent Marine Surveyor, acting DAVA PTE. LTD, to carried out Bunker Survey in order to determine the amount of bunkers remain on board. All bunker tanks were carefully sounded with the presence of Chief Engineer and the following quantities found and agreed, as calculated from the vessel's calibration tables.
D17: ='TABLES 54B'!B20 -> Very Low Sulpher Fuel Oil | E17: ='TABLES 54B'!J40 -> 466.296 | G17: M. Tons
D18: ='TABLES 54B'!B42 -> High Sulphur Fuel Oil | E18: ='TABLES 54B'!J50 -> 0 | G18: M. Tons
D19: ='TABLES 54B'!B51 -> Low Sulpher Marine Gas Oil | E19: ='TABLES 54B'!J63 -> 101.592 | G19: M. Tons
A21: The consumption from the time of survey to the time of Redelivery is calculated and verified with the Chief Engineer to be:
D23: =D17 -> Very Low Sulpher Fuel Oil | E23: ='SHIP DETAILS'!G4 -> As per Master's Report
D24: =D18 -> High Sulphur Fuel Oil | E24: ='SHIP DETAILS'!G5 -> As per Master's Report
D25: =D19 -> Low Sulpher Marine Gas Oil | E25: ='SHIP DETAILS'!G6 -> As per Master's Report
A27: Consequently, the following Bunkers was onboard at the time of Redelivery:
D29: =D17 -> Very Low Sulpher Fuel Oil | E29: ='SHIP DETAILS'!G4 -> As per Master's Report
D30: =D18 -> High Sulphur Fuel Oil | E30: ='SHIP DETAILS'!G5 -> As per Master's Report
D31: =D19 -> Low Sulpher Marine Gas Oil | E31: ='SHIP DETAILS'!G6 -> As per Master's Report
A33: REMARK: | B33: Master to confirm by E-Mail [ops@ymrmarine.com] Exact Bunker Quantities ROB at the time of redelivery.
A35: Signed On behalf of | H35: Signed On behalf of
A36: ='SHIP DETAILS'!C9 -> PRAYAN SHIPPING INC | H36: ='SHIP DETAILS'!C10 -> DAVA PTE. LTD
A42: The Master | H42: Independent Marine Surveyor | K42: Independent Marine Surveyor
A43: ='TABLES 54B'!B75 -> Capt. KAMAL PANDEY | H43: ='TABLES 54B'!G79 -> For YMR MARINE SOLUTIONS LLP | K43: For YMR MARINE SOLUTIONS
H44: ='TABLES 54B'!G80 -> Mr. ASHOK JANAPALA | K44: =CONCATENATE("Mr. ",'SHIP DETAILS'!#REF!,"") -> #REF!
A48: The Chief Engineer
A49: ='TABLES 54B'!B80 -> Mr. MUKESH KUMAR

Sheet STAMP

Sheet INTERP
D1: TRIM CORRECTION
D3: 2 | E3: 2.1 | F3: 3
B4: SOUNDING
B5: 14.2 | D5: 86.1 | E5: =D5+((F5-D5)/((F3-D3)/(E3-D3))) -> 85.21 | F5: 77.2
B6: 14.24 | D6: =(((B6-B5)/(B7-B5))*(D7-D5))+D5 -> 86.315 | E6: =((E7-E5)*((B6-B5)/(B7-B5))+E5) -> 85.425 | F6: =(((B6-B5)/(B7-B5))*(F7-F5))+F5 -> 77.41
B7: 15 | D7: 90.4 | E7: =D7+((F7-D7))/((F3-D3)/(E3-D3)) -> 89.5 | F7: 81.4
D9: BUNKERS MIXTURE
D10: DENSITIES | E10: TONS
D11: 0.9007 | E11: 0.27 | F11: =D11*E11 -> 0.243189
D12: 0.881 | E12: 9.7 | F12: =D12*E12 -> 8.5457
E13: =SUM(E11:E12) -> 9.97 | F13: =SUM(F11:F12) -> 8.788889
D14: NEW DENSITY : | F14: =F13/E13 -> 0.8815335
B17: TRANSFER DENSITY OF 20 C TO 15 C.
B19: 35 | C19: PRESENT TEMPERATURE | F19: 59 F = 15,00
B20: 15 | C20: REQUIRED TEMPERATURE | F20: 60 F = 15,55556 C
B21: =B19-B20 -> 20 | C21: DIFFERENCE
B23: 0.000629 | C23: Χ | D23: =B21 -> 20 | E23: =B23*D23 -> 0.01258
E24: 0.8545 | F24: DENSITY ON 30 C
E25: =SUM(E23:E24) -> 0.86708 | F25: DENSITY ON 15 C

Sheet REPORT
A1: REPORT_DATE
A2: REPORT_PLACE
A3: SHIP_NAME | B3: ='SHIP DETAILS'!C2 -> MV. RISHABH
A4: VOY_NO | B4: ='SHIP DETAILS'!C8 -> 15 L
A5: IMO | B5: ='SHIP DETAILS'!C3 -> 9324578
A6: GRT | B6: ='SHIP DETAILS'!C6 -> 34512
A7: PORT_OF_REGISTRY | B7: ='SHIP DETAILS'!C5 -> MAJURO
A8: ALONGSIDE
A9: HOLDS_ALPHA
A10: HOLDS | B10: 5
A11: KEEL_LAID_MONTH | B11: ='SHIP DETAILS'!C23 -> MAY
A12: KEEL_LAID_YEAR | B12: ='SHIP DETAILS'!C24 -> 2015
A13: CLASS | B13: ='SHIP DETAILS'!C32 -> NKK
A14: CALL_SIGN | B14: ='SHIP DETAILS'!C26 -> V75A45
A15: LENGTH_OVERALL | B15: ='SHIP DETAILS'!C27 -> 190.9
A16: BREDTH_MOULDED | B16: ='SHIP DETAILS'!C28 -> 32.26
A17: DEPTH_MOULDED | B17: ='SHIP DETAILS'!C29 -> 18.2
A18: SUMMER_DRAFT | B18: ='SHIP DETAILS'!C30 -> 12.2
A19: SUMMER_DEADWEIGHT | B19: ='SHIP DETAILS'!C31 -> 51874
A20: CHARTERER_NAME | B20: ='SHIP DETAILS'!C10 -> DAVA PTE. LTD
A21: OWNER_NAME | B21: ='SHIP DETAILS'!C9 -> PRAYAN SHIPPING INC
A22: BUILDER_NAME | B22: ='SHIP DETAILS'!C22 -> SOME BUILDER NAME
A23: CAPT_NAME | B23: ='SHIP DETAILS'!C17 -> KAMAL PANDEY
A24: CHIEF_ENGINEER_NAME | B24: ='SHIP DETAILS'!C18 -> MUKESH KUMAR
A25: OPERATOR_NAME | B25: ='SHIP DETAILS'!C25 -> PRAYAN SHIPPING INC
A26: SURVEYOR_NAME
A27: SURVEYOR_SIGN
A28: SURVEY_DATE | B28: ='SHIP DETAILS'!C12 -> 28th JANUARY 2026
A29: SURVEY_TIME | B29: ='SHIP DETAILS'!D13 -> 0.58333333
A30: SURVEY_PLACE | B30: ='SHIP DETAILS'!C14 -> B#6, GANGAVARAM PORT, INDIA
A31: SURVEY_VLSFO | B31: ='TABLES 54B'!J40 -> 466.296
A32: SURVEY_LSMGO | B32: ='TABLES 54B'!J63 -> 101.592
A33: SURVEY_HSFO | B33: ='TABLES 54B'!J50 -> 0
A34: SURVEY_TIME_FROM | B34: ='SHIP DETAILS'!D12 -> 0.5
A35: REDELIVERY_DATE_LT
A36: REDELIVERY_TIME_LT
A37: REDELIVERY_DATE_UTC
A38: REDELIVERY_TIME_UTC
A39: REDELIVERY_PLACE
A40: REDELIVERY_VLSFO
...
